<?xml version="1.0"?>
<robot name="my_robot_arm">

    <link name="world" />

    <joint name="fixed" type="fixed">
        <parent link="world" />
        <child link="base_link" />
    </joint>

    <link name="base_link">
        <visual>
            <geometry>
                <box size="0.2 0.2 0.06" />
            </geometry>
            <material name="white">
                <color rgba="1.0 1.0 1.0 1.0" />
            </material>
            <origin rpy="0 0 0" xyz="0 0 0.025" />
        </visual>
        <collision>
            <geometry>
                <box size="0.2 0.2 0.05" />
            </geometry>
            <origin rpy="0 0 0" xyz="0 0 0.025" />
        </collision>

        <inertial>
            <mass value="1.0" />
            <origin rpy="0 0 0" xyz="0 0 0.025" />
            <inertia ixx="0.00354" iyy="0.00354" izz="0.00667" ixy="0" ixz="0" iyz="0" />
        </inertial>
    </link>

    <joint name="hip" type="revolute">
        <parent link="base_link" />
        <child link="torso" />
        <origin rpy="0 0 0" xyz="0.0 0.0 0.05" />
        <axis xyz="0 1 0" />
        <limit lower="-3.14" upper="3.14" effort="0.5293" velocity="6.159937255" />
    </joint>

    <link name="torso">
        <visual>
            <geometry>
                <cylinder length="0.5" radius="0.05" />
            </geometry>
            <material name="white" />
            <origin rpy="0 0 0" xyz="0 0 0.25" />
        </visual>
        <collision>
            <geometry>
                <cylinder length="0.5" radius="0.05" />
            </geometry>
            <origin rpy="0 0 0" xyz="0 0 0.25" />
        </collision>
        <inertial>
            <mass value="1.0" />
            <origin rpy="0 0 0" xyz="0 0 0.25" />
            <inertia ixx="0.02146" iyy="0.02146" izz="0.00125" ixy="0" ixz="0" iyz="0" />
        </inertial>
    </link>

    <joint name="shoulder" type="revolute">
        <parent link="torso" />
        <child link="upper_arm" />
        <origin rpy="0 0 0" xyz="0.0 -0.1 0.45" />
        <axis xyz="0 1 0" />
        <limit lower="-3.14" upper="3.14" effort="0.5293" velocity="6.159937255" />
    </joint>

    <link name="upper_arm">
        <visual>
            <geometry>
                <cylinder length="0.4" radius="0.05" />
            </geometry>
            <material name="white" />
            <origin rpy="0 0 0" xyz="0 0 0.2" />
        </visual>
        <collision>
            <geometry>
                <cylinder length="0.4" radius="0.05" />
            </geometry>
            <origin rpy="0 0 0" xyz="0 0 0.2" />
        </collision>
        <inertial>
            <mass value="1.0" />
            <origin rpy="0 0 0" xyz="0 0 0.2" />
            <inertia ixx="0.01396" iyy="0.01396" izz="0.00125" ixy="0" ixz="0" iyz="0" />
        </inertial>
    </link>

    <joint name="elbow" type="revolute">
        <parent link="upper_arm" />
        <child link="lower_arm" />
        <origin rpy="0 0 0" xyz="0.0 0.1 0.35" />
        <axis xyz="0 1 0" />
        <limit lower="-3.14" upper="3.14" effort="0.5293" velocity="6.159937255" />
    </joint>

    <link name="lower_arm">
        <visual>
            <geometry>
                <cylinder length="0.4" radius="0.05" />
            </geometry>
            <material name="white" />
            <origin rpy="0 0 0" xyz="0 0 0.2" />
        </visual>
        <collision>
            <geometry>
                <cylinder length="0.4" radius="0.05" />
            </geometry>
            <origin rpy="0 0 0" xyz="0 0 0.2" />
        </collision>
        <inertial>
            <mass value="1.0" />
            <origin rpy="0 0 0" xyz="0 0 0.2" />
            <inertia ixx="0.01396" iyy="0.001396" izz="0.00125" ixy="0" ixz="0" iyz="0" />
        </inertial>
    </link>

    <joint name="wrist" type="revolute">
        <parent link="lower_arm" />
        <child link="hand" />
        <origin rpy="0 0 0" xyz="0.0 0.0 0.425" />
        <axis xyz="0 1 0" />
        <limit lower="-3.14" upper="3.14" effort="0.5293" velocity="6.159937255" />
    </joint>

    <link name="hand">
        <visual>
            <geometry>
                <cylinder length="0.15" radius="0.05" />
            </geometry>
            <material name="white" />
            <origin rpy="0 1.5708 0" xyz="0.0 0.0 0.0" />
        </visual>
        <collision>
            <geometry>
                <cylinder length="0.15" radius="0.05" />
            </geometry>
            <origin rpy="0 1.5708 0" xyz="0.0 0.0 0.0" />
        </collision>
        <inertial>
            <mass value="1.0" />
            <origin rpy="0 1.5708 0" xyz="0.0 0.0 0.0" />
            <inertia ixx="0.00250" iyy="0.00250" izz="0.00250" ixy="0" ixz="0" iyz="0" />
        </inertial>
    </link>

</robot>